<?xml version="1.0" ?>
<robot name="panda" xmlns:xacro="http://www.ros.org/wiki/xacro">
    <link name="world"/>
    <joint name="world_to_panda" type="fixed">
        <parent link="world"/>
        <child link="panda_link0"/>
        <origin xyz="0 0 0" rpy="0 0 0"/>
    </joint>

    <link name="panda_link0">
        <inertial>
            <mass value="1.0"/>
            <origin xyz="0 0 0" rpy="0 0 0"/>
            <inertia ixx="0.01" ixy="0.0" ixz="0.0" iyy="0.01" iyz="0.0" izz="0.01"/>
        </inertial>
        <visual>
            <geometry>
                <mesh filename="file://$(find mcg5353_panda_gazebo_moveit)/meshes/visual/link0.dae" />
            </geometry>
        </visual>
        <collision>
            <geometry>
                <mesh filename="file:///opt/ros/humble/share/moveit_resources_panda_description/meshes/collision/link0.stl" />
            </geometry>
        </collision>
    </link>
    <link name="panda_link1">
        <inertial>
            <mass value="1.0"/>
            <origin xyz="0 0 0" rpy="0 0 0"/>
            <inertia ixx="0.01" ixy="0.0" ixz="0.0" iyy="0.01" iyz="0.0" izz="0.01"/>
        </inertial>
        <visual>
            <geometry>
                <mesh filename="file://$(find mcg5353_panda_gazebo_moveit)/meshes/visual/link1.dae" />
            </geometry>
        </visual>
        <collision>
            <geometry>
                <mesh filename="file:///opt/ros/humble/share/moveit_resources_panda_description/meshes/collision/link1.stl" />
            </geometry>
        </collision>
    </link>
    <joint name="panda_joint1" type="revolute">
        <safety_controller k_position="100.0" k_velocity="40.0" soft_lower_limit="-2.8973" soft_upper_limit="2.8973" />
        <origin rpy="0 0 0" xyz="0 0 0.333" />
        <parent link="panda_link0" />
        <child link="panda_link1" />
        <axis xyz="0 0 1" />
        <limit effort="87" lower="-2.9671" upper="2.9671" velocity="2.3925" />
    </joint>
    <link name="panda_link2">
        <inertial>
            <mass value="1.0"/>
            <origin xyz="0 0 0" rpy="0 0 0"/>
            <inertia ixx="0.01" ixy="0.0" ixz="0.0" iyy="0.01" iyz="0.0" izz="0.01"/>
        </inertial>
        <visual>
            <geometry>
                <mesh filename="file://$(find mcg5353_panda_gazebo_moveit)/meshes/visual/link2.dae" />
            </geometry>
        </visual>
        <collision>
            <geometry>
                <mesh filename="file:///opt/ros/humble/share/moveit_resources_panda_description/meshes/collision/link2.stl" />
            </geometry>
        </collision>
    </link>
    <joint name="panda_joint2" type="revolute">
        <safety_controller k_position="100.0" k_velocity="40.0" soft_lower_limit="-1.7628" soft_upper_limit="1.7628" />
        <origin rpy="-1.57079632679 0 0" xyz="0 0 0" />
        <parent link="panda_link1" />
        <child link="panda_link2" />
        <axis xyz="0 0 1" />
        <limit effort="87" lower="-1.8326" upper="1.8326" velocity="2.3925" />
    </joint>
    <link name="panda_link3">
        <inertial>
            <mass value="1.0"/>
            <origin xyz="0 0 0" rpy="0 0 0"/>
            <inertia ixx="0.01" ixy="0.0" ixz="0.0" iyy="0.01" iyz="0.0" izz="0.01"/>
        </inertial>
        <visual>
            <geometry>
                <mesh filename="file://$(find mcg5353_panda_gazebo_moveit)/meshes/visual/link3.dae" />
            </geometry>
        </visual>
        <collision>
            <geometry>
                <mesh filename="file:///opt/ros/humble/share/moveit_resources_panda_description/meshes/collision/link3.stl" />
            </geometry>
        </collision>
    </link>
    <joint name="panda_joint3" type="revolute">
        <safety_controller k_position="100.0" k_velocity="40.0" soft_lower_limit="-2.8973" soft_upper_limit="2.8973" />
        <origin rpy="1.57079632679 0 0" xyz="0 -0.316 0" />
        <parent link="panda_link2" />
        <child link="panda_link3" />
        <axis xyz="0 0 1" />
        <limit effort="87" lower="-2.9671" upper="2.9671" velocity="2.3925" />
    </joint>
    <link name="panda_link4">
        <inertial>
            <mass value="1.0"/>
            <origin xyz="0 0 0" rpy="0 0 0"/>
            <inertia ixx="0.01" ixy="0.0" ixz="0.0" iyy="0.01" iyz="0.0" izz="0.01"/>
        </inertial>
        <visual>
            <geometry>
                <mesh filename="file://$(find mcg5353_panda_gazebo_moveit)/meshes/visual/link4.dae" />
            </geometry>
        </visual>
        <collision>
            <geometry>
                <mesh filename="file:///opt/ros/humble/share/moveit_resources_panda_description/meshes/collision/link4.stl" />
            </geometry>
        </collision>
    </link>
    <joint name="panda_joint4" type="revolute">
        <safety_controller k_position="100.0" k_velocity="40.0" soft_lower_limit="-3.0718" soft_upper_limit="0.0175" />
        <origin rpy="1.57079632679 0 0" xyz="0.0825 0 0" />
        <parent link="panda_link3" />
        <child link="panda_link4" />
        <axis xyz="0 0 1" />
        <limit effort="87" lower="-3.1416" upper="0.0873" velocity="2.3925" />
    </joint>
    <link name="panda_link5">
        <inertial>
            <mass value="1.0"/>
            <origin xyz="0 0 0" rpy="0 0 0"/>
            <inertia ixx="0.01" ixy="0.0" ixz="0.0" iyy="0.01" iyz="0.0" izz="0.01"/>
        </inertial>
        <visual>
            <geometry>
                <mesh filename="file://$(find mcg5353_panda_gazebo_moveit)/meshes/visual/link5.dae" />
            </geometry>
        </visual>
        <collision>
            <geometry>
                <mesh filename="file:///opt/ros/humble/share/moveit_resources_panda_description/meshes/collision/link5.stl" />
            </geometry>
        </collision>
    </link>
    <joint name="panda_joint5" type="revolute">
        <safety_controller k_position="100.0" k_velocity="40.0" soft_lower_limit="-2.8973" soft_upper_limit="2.8973" />
        <origin rpy="-1.57079632679 0 0" xyz="-0.0825 0.384 0" />
        <parent link="panda_link4" />
        <child link="panda_link5" />
        <axis xyz="0 0 1" />
        <limit effort="12" lower="-2.9671" upper="2.9671" velocity="2.8710" />
    </joint>
    <link name="panda_link6">
        <inertial>
            <mass value="1.0"/>
            <origin xyz="0 0 0" rpy="0 0 0"/>
            <inertia ixx="0.01" ixy="0.0" ixz="0.0" iyy="0.01" iyz="0.0" izz="0.01"/>
        </inertial>
        <visual>
            <geometry>
                <mesh filename="file://$(find mcg5353_panda_gazebo_moveit)/meshes/visual/link6.dae" />
            </geometry>
        </visual>
        <collision>
            <geometry>
                <mesh filename="file:///opt/ros/humble/share/moveit_resources_panda_description/meshes/collision/link6.stl" />
            </geometry>
        </collision>
    </link>
    <joint name="panda_joint6" type="revolute">
        <safety_controller k_position="100.0" k_velocity="40.0" soft_lower_limit="-0.0175" soft_upper_limit="3.7525" />
        <origin rpy="1.57079632679 0 0" xyz="0 0 0" />
        <parent link="panda_link5" />
        <child link="panda_link6" />
        <axis xyz="0 0 1" />
        <limit effort="12" lower="-0.0873" upper="3.8223" velocity="2.8710" />
    </joint>
    <link name="panda_link7">
        <inertial>
            <mass value="1.0"/>
            <origin xyz="0 0 0" rpy="0 0 0"/>
            <inertia ixx="0.01" ixy="0.0" ixz="0.0" iyy="0.01" iyz="0.0" izz="0.01"/>
        </inertial>
        <visual>
            <geometry>
                <mesh filename="file://$(find mcg5353_panda_gazebo_moveit)/meshes/visual/link7.dae" />
            </geometry>
        </visual>
        <collision>
            <geometry>
                <mesh filename="file:///opt/ros/humble/share/moveit_resources_panda_description/meshes/collision/link7.stl" />
            </geometry>
        </collision>
    </link>
    <joint name="panda_joint7" type="revolute">
        <safety_controller k_position="100.0" k_velocity="40.0" soft_lower_limit="-2.8973" soft_upper_limit="2.8973" />
        <origin rpy="1.57079632679 0 0" xyz="0.088 0 0" />
        <parent link="panda_link6" />
        <child link="panda_link7" />
        <axis xyz="0 0 1" />
        <limit effort="12" lower="-2.9671" upper="2.9671" velocity="2.8710" />
    </joint>
    <link name="panda_link8">
        <inertial>
            <mass value="1.0"/>
            <origin xyz="0 0 0" rpy="0 0 0"/>
            <inertia ixx="0.01" ixy="0.0" ixz="0.0" iyy="0.01" iyz="0.0" izz="0.01"/>
        </inertial>
    </link>
    <joint name="panda_joint8" type="fixed">
        <origin rpy="0 0 0" xyz="0 0 0.107" />
        <parent link="panda_link7" />
        <child link="panda_link8" />
        <axis xyz="0 0 0" />
    </joint>
    <joint name="panda_hand_joint" type="fixed">
        <parent link="panda_link8" />
        <child link="panda_hand" />
        <origin rpy="0 0 -0.785398163397" xyz="0 0 0" />
    </joint>
    <link name="panda_hand">
        <inertial>
            <mass value="1.0"/>
            <origin xyz="0 0 0" rpy="0 0 0"/>
            <inertia ixx="0.01" ixy="0.0" ixz="0.0" iyy="0.01" iyz="0.0" izz="0.01"/>
        </inertial>
        <visual>
            <geometry>
                <mesh filename="file://$(find mcg5353_panda_gazebo_moveit)/meshes/visual/hand.dae" />
            </geometry>
        </visual>
        <collision>
            <geometry>
                <mesh filename="file:///opt/ros/humble/share/moveit_resources_panda_description/meshes/collision/hand.stl" />
            </geometry>
        </collision>
    </link>
    <link name="panda_leftfinger">
        <inertial>
            <mass value="1.0"/>
            <origin xyz="0 0 0" rpy="0 0 0"/>
            <inertia ixx="0.01" ixy="0.0" ixz="0.0" iyy="0.01" iyz="0.0" izz="0.01"/>
        </inertial>
        <visual>
            <geometry>
                <mesh filename="file://$(find mcg5353_panda_gazebo_moveit)/meshes/visual/finger.dae" />
            </geometry>
        </visual>
        <collision>
            <geometry>
                <mesh filename="file:///opt/ros/humble/share/moveit_resources_panda_description/meshes/collision/finger.stl" />
            </geometry>
        </collision>
    </link>
    <link name="panda_rightfinger">
        <inertial>
            <mass value="1.0"/>
            <origin xyz="0 0 0" rpy="0 0 0"/>
            <inertia ixx="0.01" ixy="0.0" ixz="0.0" iyy="0.01" iyz="0.0" izz="0.01"/>
        </inertial>
        <visual>
            <origin rpy="0 0 3.14159265359" xyz="0 0 0" />
            <geometry>
                <mesh filename="file://$(find mcg5353_panda_gazebo_moveit)/meshes/visual/finger.dae" />
            </geometry>
        </visual>
        <collision>
            <origin rpy="0 0 3.14159265359" xyz="0 0 0" />
            <geometry>
                <mesh filename="file:///opt/ros/humble/share/moveit_resources_panda_description/meshes/collision/finger.stl" />
            </geometry>
        </collision>
    </link>
    <joint name="panda_finger_joint1" type="prismatic">
        <parent link="panda_hand" />
        <child link="panda_leftfinger" />
        <origin rpy="0 0 0" xyz="0 0 0.0584" />
        <axis xyz="0 1 0" />
        <limit effort="100" lower="0.0" upper="0.04" velocity="0.02" />
    </joint>
    <joint name="panda_finger_joint2" type="prismatic">
        <parent link="panda_hand" />
        <child link="panda_rightfinger" />
        <origin rpy="0 0 0" xyz="0 0 0.0584" />
        <axis xyz="0 -1 0" />
        <limit effort="100" lower="0.0" upper="0.04" velocity="0.02" />
        <mimic joint="panda_finger_joint1" multiplier="1.0" offset="0.0"/>
    </joint>


    <gazebo reference="panda_link0">
        <gravity>false</gravity>
        <kinematic>true</kinematic>
    </gazebo>


    <xacro:macro name="gazebo_position_joint" params="joint_name initial_value:=0.0">
        <joint name="${joint_name}">
            <command_interface name="position"/>
            <state_interface name="position">
                <param name="initial_value">${initial_value}</param>
            </state_interface>
            <state_interface name="velocity">
                <param name="initial_value">0.0</param>
            </state_interface>
        </joint>
    </xacro:macro>

    <ros2_control name="GazeboSystem" type="system">
        <hardware>
            <plugin>gazebo_ros2_control/GazeboSystem</plugin>
        </hardware>

        <xacro:gazebo_position_joint joint_name="panda_joint1" initial_value="0.0"/>
        <xacro:gazebo_position_joint joint_name="panda_joint2" initial_value="-0.785"/>
        <xacro:gazebo_position_joint joint_name="panda_joint3" initial_value="0.0"/>
        <xacro:gazebo_position_joint joint_name="panda_joint4" initial_value="-2.356"/>
        <xacro:gazebo_position_joint joint_name="panda_joint5" initial_value="0.0"/>
        <xacro:gazebo_position_joint joint_name="panda_joint6" initial_value="1.571"/>
        <xacro:gazebo_position_joint joint_name="panda_joint7" initial_value="0.785"/>

        <joint name="panda_finger_joint1">
            <command_interface name="position"/>
            <state_interface name="position">
                <param name="initial_value">0.04</param>
            </state_interface>
            <state_interface name="velocity"/>
            <state_interface name="effort"/>
        </joint>

        <joint name="panda_finger_joint2">
            <param name="mimic">panda_finger_joint1</param>
            <param name="multiplier">1</param>
            <command_interface name="position"/>
            <state_interface name="position">
                <param name="initial_value">0.04</param>
            </state_interface>
            <state_interface name="velocity"/>
            <state_interface name="effort"/>
        </joint>
    </ros2_control>

    <gazebo reference="panda_leftfinger">
      <mu1>10.0</mu1>
      <mu2>10.0</mu2>
      <kp>100000.0</kp>
      <kd>10.0</kd>
      <minDepth>0.005</minDepth>
      <maxVel>0.001</maxVel>
    </gazebo>

    <gazebo reference="panda_rightfinger">
      <mu1>10.0</mu1>
      <mu2>10.0</mu2>
      <kp>100000.0</kp>
      <kd>10.0</kd>
      <minDepth>0.005</minDepth>
      <maxVel>0.001</maxVel>
    </gazebo>

    <gazebo>
        <plugin filename="libgazebo_ros2_control.so" name="gazebo_ros2_control">
            <parameters>$(find mcg5353_panda_gazebo_moveit)/config/ros2_controllers.yaml</parameters>
        </plugin>
    </gazebo>
</robot>
